[2021-04-06 02:48:39,165] {taskinstance.py:851} INFO - Dependencies all met for <TaskInstance: udac_example_dag.Create_tables 2021-03-31T00:00:00+00:00 [queued]>
[2021-04-06 02:48:39,207] {taskinstance.py:851} INFO - Dependencies all met for <TaskInstance: udac_example_dag.Create_tables 2021-03-31T00:00:00+00:00 [queued]>
[2021-04-06 02:48:39,209] {taskinstance.py:1042} INFO - 
--------------------------------------------------------------------------------
[2021-04-06 02:48:39,209] {taskinstance.py:1043} INFO - Starting attempt 1 of 4
[2021-04-06 02:48:39,211] {taskinstance.py:1044} INFO - 
--------------------------------------------------------------------------------
[2021-04-06 02:48:39,229] {taskinstance.py:1063} INFO - Executing <Task(CreateTablesOperator): Create_tables> on 2021-03-31T00:00:00+00:00
[2021-04-06 02:48:39,235] {standard_task_runner.py:52} INFO - Started process 57 to run task
[2021-04-06 02:48:39,257] {standard_task_runner.py:76} INFO - Running: ['airflow', 'tasks', 'run', 'udac_example_dag', 'Create_tables', '2021-03-31T00:00:00+00:00', '--job-id', '9', '--pool', 'default_pool', '--raw', '--subdir', 'DAGS_FOLDER/udac_example_dag.py', '--cfg-path', '/tmp/tmpszwfopap', '--error-file', '/tmp/tmp2jjlqlap']
[2021-04-06 02:48:39,258] {standard_task_runner.py:77} INFO - Job 9: Subtask Create_tables
[2021-04-06 02:48:39,370] {logging_mixin.py:104} INFO - Running <TaskInstance: udac_example_dag.Create_tables 2021-03-31T00:00:00+00:00 [running]> on host 0ccaa9d2b3f1
[2021-04-06 02:48:39,453] {taskinstance.py:1257} INFO - Exporting the following env vars:
AIRFLOW_CTX_DAG_OWNER=udacity
AIRFLOW_CTX_DAG_ID=udac_example_dag
AIRFLOW_CTX_TASK_ID=Create_tables
AIRFLOW_CTX_EXECUTION_DATE=2021-03-31T00:00:00+00:00
AIRFLOW_CTX_DAG_RUN_ID=scheduled__2021-03-31T00:00:00+00:00
[2021-04-06 02:48:39,459] {create_tables.py:21} INFO - Creating all tables in schema:
[2021-04-06 02:48:39,504] {taskinstance.py:1455} ERROR - The conn_id `redshift` isn't defined
Traceback (most recent call last):
  File "/home/airflow/.local/lib/python3.6/site-packages/airflow/models/taskinstance.py", line 1112, in _run_raw_task
    self._prepare_and_execute_task_with_callbacks(context, task)
  File "/home/airflow/.local/lib/python3.6/site-packages/airflow/models/taskinstance.py", line 1285, in _prepare_and_execute_task_with_callbacks
    result = self._execute_task(context, task_copy)
  File "/home/airflow/.local/lib/python3.6/site-packages/airflow/models/taskinstance.py", line 1315, in _execute_task
    result = task_copy.execute(context=context)
  File "/opt/airflow/plugins/operators/create_tables.py", line 22, in execute
    [redshift.run(create_table) for create_table in SqlQueries.create_table_queries]
  File "/opt/airflow/plugins/operators/create_tables.py", line 22, in <listcomp>
    [redshift.run(create_table) for create_table in SqlQueries.create_table_queries]
  File "/home/airflow/.local/lib/python3.6/site-packages/airflow/hooks/dbapi.py", line 173, in run
    with closing(self.get_conn()) as conn:
  File "/home/airflow/.local/lib/python3.6/site-packages/airflow/providers/postgres/hooks/postgres.py", line 83, in get_conn
    conn = self.connection or self.get_connection(conn_id)
  File "/home/airflow/.local/lib/python3.6/site-packages/airflow/hooks/base.py", line 63, in get_connection
    conn = Connection.get_connection_from_secrets(conn_id)
  File "/home/airflow/.local/lib/python3.6/site-packages/airflow/models/connection.py", line 354, in get_connection_from_secrets
    raise AirflowNotFoundException(f"The conn_id `{conn_id}` isn't defined")
airflow.exceptions.AirflowNotFoundException: The conn_id `redshift` isn't defined
[2021-04-06 02:48:39,510] {taskinstance.py:1503} INFO - Marking task as UP_FOR_RETRY. dag_id=udac_example_dag, task_id=Create_tables, execution_date=20210331T000000, start_date=20210406T024839, end_date=20210406T024839
[2021-04-06 02:48:39,593] {local_task_job.py:146} INFO - Task exited with return code 1
