[2021-04-06 03:04:29,325] {taskinstance.py:851} INFO - Dependencies all met for <TaskInstance: udac_example_dag.Create_tables 2021-03-28T00:00:00+00:00 [queued]>
[2021-04-06 03:04:29,503] {taskinstance.py:851} INFO - Dependencies all met for <TaskInstance: udac_example_dag.Create_tables 2021-03-28T00:00:00+00:00 [queued]>
[2021-04-06 03:04:29,525] {taskinstance.py:1042} INFO - 
--------------------------------------------------------------------------------
[2021-04-06 03:04:29,526] {taskinstance.py:1043} INFO - Starting attempt 3 of 4
[2021-04-06 03:04:29,530] {taskinstance.py:1044} INFO - 
--------------------------------------------------------------------------------
[2021-04-06 03:04:29,644] {taskinstance.py:1063} INFO - Executing <Task(CreateTablesOperator): Create_tables> on 2021-03-28T00:00:00+00:00
[2021-04-06 03:04:29,747] {standard_task_runner.py:76} INFO - Running: ['airflow', 'tasks', 'run', 'udac_example_dag', 'Create_tables', '2021-03-28T00:00:00+00:00', '--job-id', '31', '--pool', 'default_pool', '--raw', '--subdir', 'DAGS_FOLDER/udac_example_dag.py', '--cfg-path', '/tmp/tmpi7y3vcp6', '--error-file', '/tmp/tmp3en3db0i']
[2021-04-06 03:04:29,779] {standard_task_runner.py:77} INFO - Job 31: Subtask Create_tables
[2021-04-06 03:04:29,758] {standard_task_runner.py:52} INFO - Started process 109 to run task
[2021-04-06 03:04:30,315] {logging_mixin.py:104} INFO - Running <TaskInstance: udac_example_dag.Create_tables 2021-03-28T00:00:00+00:00 [running]> on host 0ccaa9d2b3f1
[2021-04-06 03:04:31,292] {taskinstance.py:1257} INFO - Exporting the following env vars:
AIRFLOW_CTX_DAG_OWNER=udacity
AIRFLOW_CTX_DAG_ID=udac_example_dag
AIRFLOW_CTX_TASK_ID=Create_tables
AIRFLOW_CTX_EXECUTION_DATE=2021-03-28T00:00:00+00:00
AIRFLOW_CTX_DAG_RUN_ID=scheduled__2021-03-28T00:00:00+00:00
[2021-04-06 03:04:31,300] {create_tables.py:21} INFO - Creating all tables in schema:
[2021-04-06 03:04:31,631] {base.py:74} INFO - Using connection to: id: redshift. Host: sparkify-redshift.c5c7ovgg2wrr.us-west-2.redshift.amazonaws.com, Port: 5439, Schema: sparkify-song-analytics, Login: data.engineer, Password: XXXXXXXX, extra: None
[2021-04-06 03:04:32,568] {dbapi.py:180} INFO - Running statement: 
        BEGIN;
        DROP TABLE IF EXISTS staging_events;
        CREATE TABLE staging_events (
            artist varchar(256),
            auth varchar(256),
            firstname varchar(256),
            gender varchar(256),
            iteminsession int4,
            lastname varchar(256),
            length numeric(18,0),
            "level" varchar(256),
            location varchar(256),
            "method" varchar(256),
            page varchar(256),
            registration numeric(18,0),
            sessionid int4,
            song varchar(256),
            status int4,
            ts int8,
            useragent varchar(256),
            userid int4
        );
        COMMIT;
    , parameters: None
[2021-04-06 03:04:32,901] {taskinstance.py:1455} ERROR - could not open relation with OID 101559
Traceback (most recent call last):
  File "/home/airflow/.local/lib/python3.6/site-packages/airflow/models/taskinstance.py", line 1112, in _run_raw_task
    self._prepare_and_execute_task_with_callbacks(context, task)
  File "/home/airflow/.local/lib/python3.6/site-packages/airflow/models/taskinstance.py", line 1285, in _prepare_and_execute_task_with_callbacks
    result = self._execute_task(context, task_copy)
  File "/home/airflow/.local/lib/python3.6/site-packages/airflow/models/taskinstance.py", line 1315, in _execute_task
    result = task_copy.execute(context=context)
  File "/opt/airflow/plugins/operators/create_tables.py", line 22, in execute
    [redshift.run(create_table) for create_table in SqlQueries.create_table_queries]
  File "/opt/airflow/plugins/operators/create_tables.py", line 22, in <listcomp>
    [redshift.run(create_table) for create_table in SqlQueries.create_table_queries]
  File "/home/airflow/.local/lib/python3.6/site-packages/airflow/hooks/dbapi.py", line 184, in run
    cur.execute(sql_statement)
psycopg2.errors.InternalError_: could not open relation with OID 101559

[2021-04-06 03:04:32,924] {taskinstance.py:1503} INFO - Marking task as UP_FOR_RETRY. dag_id=udac_example_dag, task_id=Create_tables, execution_date=20210328T000000, start_date=20210406T030429, end_date=20210406T030432
[2021-04-06 03:04:32,971] {local_task_job.py:146} INFO - Task exited with return code 1
