[2021-04-06 03:13:17,054] {taskinstance.py:851} INFO - Dependencies all met for <TaskInstance: udac_example_dag.Run_data_quality_checks 2021-03-26T00:00:00+00:00 [queued]>
[2021-04-06 03:13:17,073] {taskinstance.py:851} INFO - Dependencies all met for <TaskInstance: udac_example_dag.Run_data_quality_checks 2021-03-26T00:00:00+00:00 [queued]>
[2021-04-06 03:13:17,075] {taskinstance.py:1042} INFO - 
--------------------------------------------------------------------------------
[2021-04-06 03:13:17,076] {taskinstance.py:1043} INFO - Starting attempt 2 of 4
[2021-04-06 03:13:17,077] {taskinstance.py:1044} INFO - 
--------------------------------------------------------------------------------
[2021-04-06 03:13:17,091] {taskinstance.py:1063} INFO - Executing <Task(DataQualityOperator): Run_data_quality_checks> on 2021-03-26T00:00:00+00:00
[2021-04-06 03:13:17,097] {standard_task_runner.py:52} INFO - Started process 185 to run task
[2021-04-06 03:13:17,101] {standard_task_runner.py:76} INFO - Running: ['airflow', 'tasks', 'run', 'udac_example_dag', 'Run_data_quality_checks', '2021-03-26T00:00:00+00:00', '--job-id', '74', '--pool', 'default_pool', '--raw', '--subdir', 'DAGS_FOLDER/udac_example_dag.py', '--cfg-path', '/tmp/tmpid153xyb', '--error-file', '/tmp/tmp5vnkd56o']
[2021-04-06 03:13:17,103] {standard_task_runner.py:77} INFO - Job 74: Subtask Run_data_quality_checks
[2021-04-06 03:13:17,152] {logging_mixin.py:104} INFO - Running <TaskInstance: udac_example_dag.Run_data_quality_checks 2021-03-26T00:00:00+00:00 [running]> on host 0ccaa9d2b3f1
[2021-04-06 03:13:17,192] {taskinstance.py:1257} INFO - Exporting the following env vars:
AIRFLOW_CTX_DAG_OWNER=udacity
AIRFLOW_CTX_DAG_ID=udac_example_dag
AIRFLOW_CTX_TASK_ID=Run_data_quality_checks
AIRFLOW_CTX_EXECUTION_DATE=2021-03-26T00:00:00+00:00
AIRFLOW_CTX_DAG_RUN_ID=scheduled__2021-03-26T00:00:00+00:00
[2021-04-06 03:13:17,202] {base.py:74} INFO - Using connection to: id: redshift. Host: sparkify-redshift.c5c7ovgg2wrr.us-west-2.redshift.amazonaws.com, Port: 5439, Schema: sparkify-song-analytics, Login: data.engineer, Password: XXXXXXXX, extra: None
[2021-04-06 03:13:18,961] {taskinstance.py:1455} ERROR - Data quality check failed. staging_events contained 0 rows
Traceback (most recent call last):
  File "/home/airflow/.local/lib/python3.6/site-packages/airflow/models/taskinstance.py", line 1112, in _run_raw_task
    self._prepare_and_execute_task_with_callbacks(context, task)
  File "/home/airflow/.local/lib/python3.6/site-packages/airflow/models/taskinstance.py", line 1285, in _prepare_and_execute_task_with_callbacks
    result = self._execute_task(context, task_copy)
  File "/home/airflow/.local/lib/python3.6/site-packages/airflow/models/taskinstance.py", line 1315, in _execute_task
    result = task_copy.execute(context=context)
  File "/opt/airflow/plugins/operators/data_quality.py", line 31, in execute
    raise ValueError(f"Data quality check failed. {table} contained 0 rows")
ValueError: Data quality check failed. staging_events contained 0 rows
[2021-04-06 03:13:18,968] {taskinstance.py:1503} INFO - Marking task as UP_FOR_RETRY. dag_id=udac_example_dag, task_id=Run_data_quality_checks, execution_date=20210326T000000, start_date=20210406T031317, end_date=20210406T031318
[2021-04-06 03:13:19,033] {local_task_job.py:146} INFO - Task exited with return code 1
